data/sample_events.csv
timestamp,symbol,type,side,order_id,price,quantity
1,AAPL,ADD,BUY,1101,100,100
2,AAPL,ADD,BUY,1102,99,80
3,AAPL,ADD,SELL,1103,102,60
4,AAPL,ADD,SELL,1104,100,40
5,AAPL,MARKET,BUY,1105,,50
6,AAPL,CANCEL,,1102,,
7,MSFT,ADD,SELL,2101,205,70
8,MSFT,ADD,BUY,2102,204,50
9,MSFT,ADD,BUY,2103,205,30
10,MSFT,MARKET,SELL,2104,,60
11,MSFT,CANCEL,,2102,,
12,BTCUSD,ADD,BUY,3101,60000,2
13,BTCUSD,ADD,SELL,3102,60005,1
14,BTCUSD,MARKET,BUY,3103,,1
15,BTCUSD,ADD,SELL,3104,60000,3
16,BTCUSD,CANCEL,,3104,,
